Workbook

Sheet Sheet3
A1: Q1-i Variance-Covariance Matrix
B2: BCS | C2: BAC | D2: JPM | E2: C | F2: BMO | G2: M | H2: DE | I2: PG | J2: SWK | K2: PFE | L2: AXP | M2: NYT | N2: WFC | O2: TD | P2: AAPL | Q2: AMZN | R2: MSFT | S2: IBM
A3: BCS | B3: =VARP('Q1'!$W$2:$W$299) -> 0.014857202 | C3: 0.01278067 | D3: 0.0097855514 | E3: 0.013332538 | F3: 0.0081715908 | G3: 0.010762256 | H3: 0.0077945816 | I3: 0.0043570681 | J3: 0.0086258017 | K3: 0.005183452 | L3: 0.010353882 | M3: 0.0073924292 | N3: 0.0095598116 | O3: 0.007796888 | P3: 0.0061539409 | Q3: 0.0056473496 | R3: 0.0060029117 | S3: 0.0059377608 | X3: E[r] | Y3: E[r] - c | AA3: Mean | AB3: =AVERAGE('Q1'!W2:W299) -> 0.0081404368 | AC3: =AVERAGE('Q1'!X2:X299) -> 0.0068453663 | AD3: =AVERAGE('Q1'!Y2:Y299) -> 0.0074872864 | AE3: =AVERAGE('Q1'!Z2:Z299) -> -0.00054653586 | AF3: =AVERAGE('Q1'!AA2:AA299) -> 0.0085277978 | AG3: =AVERAGE('Q1'!AB2:AB299) -> 0.0061527846 | AH3: =AVERAGE('Q1'!AC2:AC299) -> 0.01151211 | AI3: =AVERAGE('Q1'!AD2:AD299) -> 0.0041850898 | ... AS3: =AVERAGE('Q1'!AN2:AN299) -> 0.0035001014
A4: BAC | B4: 0.01278067 | C4: =VARP('Q1'!$X$2:$X$299) -> 0.015564999 | D4: 0.010307798 | E4: 0.013743723 | F4: 0.0079048924 | G4: 0.009242453 | H4: 0.0071197978 | I4: 0.0043476261 | J4: 0.0074426493 | K4: 0.0056257171 | L4: 0.0089055956 | M4: 0.007720327 | N4: 0.010306591 | O4: 0.0077189346 | P4: 0.0061483785 | Q4: 0.0057151276 | R4: 0.0060790327 | S4: 0.0058658976 | X4: {=TRANSPOSE(AB3:AS3)} -> 0.0081404368 | Y4: =X4-$V$8 -> -0.021859563
A5: JPM | B5: 0.0097855514 | C5: 0.010307798 | D5: =VARP('Q1'!$Y$2:$Y$299) -> 0.010597621 | E5: 0.010323741 | F5: 0.0066939385 | G5: 0.0086290137 | H5: 0.0062089351 | I5: 0.0039892157 | J5: 0.006863176 | K5: 0.0050179832 | L5: 0.0077730164 | M5: 0.0068738691 | N5: 0.0078778826 | O5: 0.0070296013 | P5: 0.0061737721 | Q5: 0.0062661643 | R5: 0.00614113 | S5: 0.0062229403 | X5: 0.0068453663 | Y5: =X5-$V$8 -> -0.023154634
A6: C | B6: 0.013332538 | C6: 0.013743723 | D6: 0.010323741 | E6: =VARP('Q1'!$Z$2:$Z$299) -> 0.016865827 | F6: 0.0080694505 | G6: 0.0098797673 | H6: 0.0075800744 | I6: 0.0043438005 | J6: 0.0079280575 | K6: 0.0057304461 | L6: 0.0098345184 | M6: 0.0077618236 | N6: 0.0099752943 | O6: 0.0080172249 | P6: 0.0068157814 | Q6: 0.006566965 | R6: 0.0068744453 | S6: 0.0066776438 | X6: 0.0074872864 | Y6: =X6-$V$8 -> -0.022512714
A7: BMO | B7: 0.0081715908 | C7: 0.0079048924 | D7: 0.0066939385 | E7: 0.0080694505 | F7: =VARP('Q1'!$AA$2:$AA$299) -> 0.0083736862 | G7: 0.0076478624 | H7: 0.0062170475 | I7: 0.0040312723 | J7: 0.0062962127 | K7: 0.0046134077 | L7: 0.007309075 | M7: 0.0058904736 | N7: 0.0069484129 | O7: 0.0070332294 | P7: 0.0052717784 | Q7: 0.0047955555 | R7: 0.0048133183 | S7: 0.0051446951 | X7: -0.00054653586 | Y7: =X7-$V$8 -> -0.030546536
A8: M | B8: 0.010762256 | C8: 0.009242453 | D8: 0.0086290137 | E8: 0.0098797673 | F8: 0.0076478624 | G8: =VARP('Q1'!$AB$2:$AB$299) -> 0.019794899 | H8: 0.0076544534 | I8: 0.0041501121 | J8: 0.0083350875 | K8: 0.0051266327 | L8: 0.0088945371 | M8: 0.0069446358 | N8: 0.0080767884 | O8: 0.0074549227 | P8: 0.0069807442 | Q8: 0.0070998836 | R8: 0.0064125394 | S8: 0.0060835914 | U8: C = | V8: 0.03 | X8: 0.0085277978 | Y8: =X8-$V$8 -> -0.021472202
A9: DE | B9: 0.0077945816 | C9: 0.0071197978 | D9: 0.0062089351 | E9: 0.0075800744 | F9: 0.0062170475 | G9: 0.0076544534 | H9: =VARP('Q1'!$AC$2:$AC$299) -> 0.010174936 | I9: 0.0045183734 | J9: 0.0073767874 | K9: 0.0047659548 | L9: 0.0070281442 | M9: 0.0061559254 | N9: 0.0060897366 | O9: 0.0058939262 | P9: 0.0053628468 | Q9: 0.0060061791 | R9: 0.0048441918 | S9: 0.0050812582 | X9: 0.0061527846 | Y9: =X9-$V$8 -> -0.023847215
A10: PG | B10: 0.0043570681 | C10: 0.0043476261 | D10: 0.0039892157 | E10: 0.0043438005 | F10: 0.0040312723 | G10: 0.0041501121 | H10: 0.0045183734 | I10: =VARP('Q1'!$AD$2:$AD$299) -> 0.005966182 | J10: 0.0043294838 | K10: 0.0041120163 | L10: 0.0044387396 | M10: 0.0042614815 | N10: 0.0041172352 | O10: 0.004161042 | P10: 0.0032680492 | Q10: 0.0039850621 | R10: 0.0033571609 | S10: 0.0036596816 | X10: 0.01151211 | Y10: =X10-$V$8 -> -0.01848789
A11: SWK | B11: 0.0086258017 | C11: 0.0074426493 | D11: 0.006863176 | E11: 0.0079280575 | F11: 0.0062962127 | G11: 0.0083350875 | H11: 0.0073767874 | I11: 0.0043294838 | J11: =VARP('Q1'!$AE$2:$AE$299) -> 0.010520461 | K11: 0.0048670711 | L11: 0.007376398 | M11: 0.0065004294 | N11: 0.0061955324 | O11: 0.0061772786 | P11: 0.006324829 | Q11: 0.005731706 | R11: 0.0052283776 | S11: 0.0058202161 | X11: 0.0041850898 | Y11: =X11-$V$8 -> -0.02581491
A12: PFE | B12: 0.005183452 | C12: 0.0056257171 | D12: 0.0050179832 | E12: 0.0057304461 | F12: 0.0046134077 | G12: 0.0051266327 | H12: 0.0047659548 | I12: 0.0041120163 | J12: 0.0048670711 | K12: =VARP('Q1'!$AF$2:$AF$299) -> 0.0070217759 | L12: 0.0044952723 | M12: 0.0047804672 | N12: 0.0049135361 | O12: 0.0045549522 | P12: 0.0039125742 | Q12: 0.0042145554 | R12: 0.0044165885 | S12: 0.004461987 | X12: 0.006698431 | Y12: =X12-$V$8 -> -0.023301569
A13: AXP | B13: 0.010353882 | C13: 0.0089055956 | D13: 0.0077730164 | E13: 0.0098345184 | F13: 0.007309075 | G13: 0.0088945371 | H13: 0.0070281442 | I13: 0.0044387396 | J13: 0.007376398 | K13: 0.0044952723 | L13: =VARP('Q1'!$AG$2:$AG$299) -> 0.011526552 | M13: 0.0068201402 | N13: 0.008045064 | O13: 0.0068286895 | P13: 0.006335407 | Q13: 0.0067886595 | R13: 0.0055964508 | S13: 0.0057218457 | X13: 0.00072614052 | Y13: =X13-$V$8 -> -0.029273859
A14: NYT | B14: 0.0073924292 | C14: 0.007720327 | D14: 0.0068738691 | E14: 0.0077618236 | F14: 0.0058904736 | G14: 0.0069446358 | H14: 0.0061559254 | I14: 0.0042614815 | J14: 0.0065004294 | K14: 0.0047804672 | L14: 0.0068201402 | M14: =VARP('Q1'!$AH$2:$AH$299) -> 0.013439109 | N14: 0.0063933902 | O14: 0.0059482729 | P14: 0.0053888443 | Q14: 0.0055556707 | R14: 0.0054399176 | S14: 0.0048718686 | X14: 0.0073065422 | Y14: =X14-$V$8 -> -0.022693458
A15: WFC | B15: 0.0095598116 | C15: 0.010306591 | D15: 0.0078778826 | E15: 0.0099752943 | F15: 0.0069484129 | G15: 0.0080767884 | H15: 0.0060897366 | I15: 0.0041172352 | J15: 0.0061955324 | K15: 0.0049135361 | L15: 0.008045064 | M15: 0.0063933902 | N15: =VARP('Q1'!$AI$2:$AI$299) -> 0.010266059 | O15: 0.0064537428 | P15: 0.0041098173 | Q15: 0.0042576689 | R15: 0.0044760435 | S15: 0.0045402516 | X15: 0.0032794129 | Y15: =X15-$V$8 -> -0.026720587
A16: TD | B16: 0.007796888 | C16: 0.0077189346 | D16: 0.0070296013 | E16: 0.0080172249 | F16: 0.0070332294 | G16: 0.0074549227 | H16: 0.0058939262 | I16: 0.004161042 | J16: 0.0061772786 | K16: 0.0045549522 | L16: 0.0068286895 | M16: 0.0059482729 | N16: 0.0064537428 | O16: =VARP('Q1'!$AJ$2:$AJ$299) -> 0.0080594394 | P16: 0.0059939616 | Q16: 0.0056307585 | R16: 0.0049446115 | S16: 0.0055257442 | X16: 0.006384616 | Y16: =X16-$V$8 -> -0.023615384
A17: AAPL | B17: 0.0061539409 | C17: 0.0061483785 | D17: 0.0061737721 | E17: 0.0068157814 | F17: 0.0052717784 | G17: 0.0069807442 | H17: 0.0053628468 | I17: 0.0032680492 | J17: 0.006324829 | K17: 0.0039125742 | L17: 0.006335407 | M17: 0.0053888443 | N17: 0.0041098173 | O17: 0.0059939616 | P17: =VARP('Q1'!$AK$2:$AK$299) -> 0.01570632 | Q17: 0.0093169486 | R17: 0.0076356253 | S17: 0.0067772586 | X17: 0.0071863703 | Y17: =X17-$V$8 -> -0.02281363
A18: AMZN | B18: 0.0056473496 | C18: 0.0057151276 | D18: 0.0062661643 | E18: 0.006566965 | F18: 0.0047955555 | G18: 0.0070998836 | H18: 0.0060061791 | I18: 0.0039850621 | J18: 0.005731706 | K18: 0.0042145554 | L18: 0.0067886595 | M18: 0.0055556707 | N18: 0.0042576689 | O18: 0.0056307585 | P18: 0.0093169486 | Q18: =VARP('Q1'!$AL$2:$AL$299) -> 0.019794832 | R18: 0.0078245938 | S18: 0.0069412993 | X18: 0.022335198 | Y18: =X18-$V$8 -> -0.0076648019
A19: MSFT | B19: 0.0060029117 | C19: 0.0060790327 | D19: 0.00614113 | E19: 0.0068744453 | F19: 0.0048133183 | G19: 0.0064125394 | H19: 0.0048441918 | I19: 0.0033571609 | J19: 0.0052283776 | K19: 0.0044165885 | L19: 0.0055964508 | M19: 0.0054399176 | N19: 0.0044760435 | O19: 0.0049446115 | P19: 0.0076356253 | Q19: 0.0078245938 | R19: =VARP('Q1'!$AM$2:$AM$299) -> 0.0098338453 | S19: 0.006095224 | X19: 0.018372167 | Y19: =X19-$V$8 -> -0.011627833
A20: IBM | B20: 0.0059377608 | C20: 0.0058658976 | D20: 0.0062229403 | E20: 0.0066776438 | F20: 0.0051446951 | G20: 0.0060835914 | H20: 0.0050812582 | I20: 0.0036596816 | J20: 0.0058202161 | K20: 0.004461987 | L20: 0.0057218457 | M20: 0.0048718686 | N20: 0.0045402516 | O20: 0.0055257442 | P20: 0.0067772586 | Q20: 0.0069412993 | R20: 0.006095224 | S20: =VARP('Q1'!$AN$2:$AN$299) -> 0.0085473119 | X20: 0.0085926715 | Y20: =X20-$V$8 -> -0.021407329
X21: 0.0035001014 | Y21: =X21-$V$8 -> -0.026499899
A23: z | B23: Port Weight (wi) | D23: z | E23: Port Weight (wi)
A24: {=MMULT(MINVERSE(B3:S20),_xlfn.ANCHORARRAY(X4))} -> 1.4611929 | B24: =A24/(SUM($A$24:$A$41)) -> 1.1270091 | D24: {=MMULT(MINVERSE(B3:S20),Y4:Y21)} -> 1.3381502 | E24: =D24/(SUM($D$24:$D$41)) -> -0.25812815
A25: 0.19685657 | B25: =A25/(SUM($A$24:$A$41)) -> 0.15183426 | D25: 0.79252037 | E25: =D25/(SUM($D$24:$D$41)) -> -0.15287657
A26: 0.8280409 | B26: =A26/(SUM($A$24:$A$41)) -> 0.63866285 | D26: 0.75021284 | E26: =D26/(SUM($D$24:$D$41)) -> -0.14471548
A27: -2.4144074 | B27: =A27/(SUM($A$24:$A$41)) -> -1.8622176 | D27: -1.7502584 | E27: =D27/(SUM($D$24:$D$41)) -> 0.33762351
A28: 1.2337276 | B28: =A28/(SUM($A$24:$A$41)) -> 0.95156649 | D28: 0.63073592 | E28: =D28/(SUM($D$24:$D$41)) -> -0.12166848
A29: -0.48901156 | B29: =A29/(SUM($A$24:$A$41)) -> -0.37717161 | D29: -0.27101464 | E29: =D29/(SUM($D$24:$D$41)) -> 0.052278516
A30: 1.3585929 | B30: =A30/(SUM($A$24:$A$41)) -> 1.0478744 | D30: 1.2253688 | E30: =D30/(SUM($D$24:$D$41)) -> -0.2363727
A31: 0.16687422 | B31: =A31/(SUM($A$24:$A$41)) -> 0.12870906 | D31: -2.5243784 | E31: =D31/(SUM($D$24:$D$41)) -> 0.48695067
A32: -0.55721895 | B32: =A32/(SUM($A$24:$A$41)) -> -0.42977955 | D32: -0.4826643 | E32: =D32/(SUM($D$24:$D$41)) -> 0.093105574
A33: -1.113265 | B33: =A33/(SUM($A$24:$A$41)) -> -0.85865447 | D33: -2.3025487 | E33: =D33/(SUM($D$24:$D$41)) -> 0.44415988
A34: -0.85158317 | B34: =A34/(SUM($A$24:$A$41)) -> -0.65682086 | D34: -0.50689107 | E34: =D34/(SUM($D$24:$D$41)) -> 0.097778901
A35: -0.46392556 | B35: =A35/(SUM($A$24:$A$41)) -> -0.35782293 | D35: -0.57388121 | E35: =D35/(SUM($D$24:$D$41)) -> 0.11070125
A36: 1.0996524 | B36: =A36/(SUM($A$24:$A$41)) -> 0.84815511 | D36: -0.18482268 | E36: =D36/(SUM($D$24:$D$41)) -> 0.035652153
... A41: -1.2758135 | B41: =A41/(SUM($A$24:$A$41)) -> -0.98402713 | D41: -2.0622021 | E41: =D41/(SUM($D$24:$D$41)) -> 0.3977972
A44: Expected return | B44: {=MMULT(TRANSPOSE(B24:B41),X4:X21)} -> 0.065513986 | C44: {=MMULT(TRANSPOSE(E24:E41),X4:X21)} -> -0.0088819856
A45: Variance | B45: {=MMULT(MMULT(TRANSPOSE(B24:B41),B3:S20),B24:B41)} -> 0.050530535 | C45: {=MMULT(MMULT(TRANSPOSE(E24:E41),B3:S20),E24:E41)} -> 0.0075003053
A46: Stdev | B46: =B45^0.5 -> 0.22478998 | C46: =C45^0.5 -> 0.086604303
A48: Cov(x,y) | B48: {=MMULT(MMULT(TRANSPOSE(B24:B41),B3:S20),E24:E41)} -> -0.0068506208
...

Sheet Q1
A1: date | B1: BCS | C1: BAC | D1: JPM | E1: C | F1: BMO | G1: M | H1: DE | I1: PG | J1: SWK | K1: PFE | L1: AXP | M1: NYT | N1: WFC | O1: TD | P1: AAPL | Q1: AMZN | R1: MSFT | S1: IBM | V1: date | W1: BCS | X1: BAC | Y1: JPM | Z1: C | AA1: BMO | AB1: M | AC1: DE | AD1: PG | AE1: SWK | AF1: PFE | AG1: AXP | AH1: NYT | AI1: WFC | AJ1: TD | AK1: AAPL | AL1: AMZN | AM1: MSFT | AN1: IBM
A2: 36526 | B2: 9.444137 | C2: 12.490797 | D2: 25.48102 | E2: 223.44882 | F2: 5.332372 | G2: 10.871688 | H2: 13.243672 | I2: 25.479961 | J2: 12.81861 | K2: 13.227181 | L2: 33.865257 | M2: 33.154583 | N2: 9.864648 | O2: 4.590513 | P2: 0.777893 | Q2: 3.228125 | R2: 29.949718 | S2: 55.557552 | V2: 36526 | W2: =(B3-B2)/B2 -> 0.0051018955 | X2: =(C3-C2)/C2 -> -0.050322089 | Y2: =(D3-D2)/D2 -> -0.0075844688 | Z2: =(E3-E2)/E2 -> -0.092105185 | AA2: =(F3-F2)/F2 -> -0.084586184 | AB2: =(G3-G2)/G2 -> -0.11861847 | AC2: =(H3-H2)/H2 -> -0.1816879 | AD2: =(I3-I2)/I2 -> -0.12810235 | ... AN2: =(S3-S2)/S2 -> -0.084632059
A3: 36557 | B3: 9.49232 | C3: 11.862234 | D3: 25.28776 | E3: 202.86803 | F3: 4.881327 | G3: 9.582105 | H3: 10.837457 | I3: 22.215918 | J3: 11.734449 | K3: 11.74227 | L3: 27.62406 | M3: 30.660074 | N3: 8.153743 | O3: 4.613241 | P3: 0.859431 | Q3: 3.44375 | R3: 27.348722 | S3: 50.855602 | V3: 36557 | W3: =(B4-B3)/B3 -> 0.1425662 | X3: =(C4-C3)/C3 -> 0.13994548 | Y3: =(D4-D3)/D3 -> 0.094976265 | Z3: =(E4-E3)/E3 -> 0.16021869 | AA3: =(F4-F3)/F3 -> 0.17109999 | AB3: =(G4-G3)/G3 -> 0.15161815 | AC3: =(H4-H3)/H3 -> 0.06293672 | AD3: =(I4-I3)/I3 -> -0.35419617 | ... AN3: =(S4-S3)/S3 -> 0.15328024
A4: 36586 | B4: 10.845604 | C4: 13.5223 | D4: 27.689497 | E4: 235.37128 | F4: 5.716522 | G4: 11.034926 | H4: 11.519531 | I4: 14.347125 | J4: 13.456355 | K4: 13.398168 | L4: 30.660519 | M4: 31.24161 | N4: 10.10458 | O4: 4.851855 | P4: 1.01829 | Q4: 3.35 | R4: 32.512463 | S4: 58.650761 | V4: 36586 | W4: =(B5-B4)/B4 -> 0 | X4: =(C5-C4)/C4 -> -0.055285565 | Y4: =(D5-D4)/D4 -> -0.17275995 | Z4: =(E5-E4)/E4 -> -0.014613142 | AA4: =(F5-F4)/F4 -> 0.044484216 | AB4: =(G5-G4)/G4 -> -0.19526592 | AC4: =(H5-H4)/H4 -> 0.068877283 | AD4: =(I5-I4)/I4 -> 0.052863065 | ... AN4: =(S5-S4)/S4 -> -0.058077865
A5: 36617 | B5: 10.845604 | C5: 12.774712 | D5: 22.905861 | E5: 231.93176 | F5: 5.970817 | G5: 8.880181 | H5: 12.312965 | I5: 15.105558 | J5: 15.195655 | K5: 15.436522 | L5: 30.776304 | M5: 29.968321 | N5: 10.182076 | O5: 4.24007 | P5: 0.930191 | Q5: 2.759375 | R5: 21.343477 | S5: 55.24445 | V5: 36617 | W5: =(B6-B5)/B5 -> -0.02727234 | X5: =(C6-C5)/C5 -> 0.13137729 | Y5: =(D6-D5)/D5 -> 0.040929568 | Z5: =(E6-E5)/E5 -> 0.056730315 | AA5: =(F6-F5)/F5 -> 0.10902897 | AB5: =(G6-G5)/G5 -> 0.13235293 | AC5: =(H6-H5)/H5 -> 0.029412168 | AD5: =(I6-I5)/I5 -> 0.11815671 | ... AN5: =(S6-S5)/S5 -> -0.037555863
A6: 36647 | B6: 10.549819 | C6: 14.453019 | D6: 23.843388 | E6: 245.08933 | F6: 6.621809 | G6: 10.055499 | H6: 12.675116 | I6: 16.890381 | J6: 13.843509 | K6: 16.306826 | L6: 33.407055 | M6: 28.058348 | N6: 11.220428 | O6: 4.503644 | P6: 0.629812 | Q6: 2.415625 | R6: 19.1441 | S6: 53.169697 | V6: 36647 | W6: =(B7-B6)/B6 -> -0.065420743 | X6: =(C7-C6)/C6 -> -0.21722749 | Y6: =(D7-D6)/D6 -> -0.074894809 | Z6: =(E7-E6)/E6 -> -0.031155808 | AA6: =(F7-F6)/F6 -> 0.063527202 | AB6: =(G7-G6)/G6 -> -0.12337667 | AC6: =(H7-H6)/H6 -> -0.1097747 | AD6: =(I7-I6)/I6 -> -0.1466167 | ... AN6: =(S7-S6)/S6 -> 0.02219834
A7: 36678 | B7: 9.859642 | C7: 11.313426 | D7: 22.057642 | E7: 237.45337 | F7: 7.042474 | G7: 8.814885 | H7: 11.283709 | I7: 14.413969 | J7: 12.233794 | K7: 17.623777 | L7: 32.247082 | M7: 28.827568 | N7: 9.660019 | O7: 4.457804 | P7: 0.785391 | Q7: 1.815625 | R7: 24.479969 | S7: 54.349976 | V7: 36678 | W7: =(B8-B7)/B7 -> -0.091250271 | X7: =(C8-C7)/C7 -> 0.10174433 | Y7: =(D8-D7)/D7 -> 0.081411331 | Z7: =(E8-E7)/E7 -> 0.17012451 | AA7: =(F8-F7)/F7 -> 0.0073204388 | AB7: =(G8-G7)/G7 -> -0.28703721 | AC7: =(H8-H7)/H7 -> 0.048123272 | AD7: =(I8-I7)/I7 -> 0.0044052405 | ... AN7: =(S8-S7)/S7 -> 0.024529247
A8: 36708 | B8: 8.959947 | C8: 12.464503 | D8: 23.853384 | E8: 277.85001 | F8: 7.094028 | G8: 6.284685 | H8: 11.826718 | I8: 14.477466 | J8: 13.600714 | K8: 15.92565 | L8: 35.069672 | M8: 30.059128 | N8: 10.345565 | O8: 4.420399 | P8: 0.76196 | Q8: 1.50625 | R8: 21.362597 | S8: 55.68314 | V8: 36708 | W8: =(B9-B8)/B8 -> 0.13342534 | X8: =(C9-C8)/C8 -> 0.13093695 | Y8: =(D9-D8)/D8 -> 0.12955378 | Z8: =(E9-E8)/E8 -> 0.10431432 | AA8: =(F9-F8)/F8 -> -0.042151229 | AB8: =(G9-G8)/G8 -> 0.14870149 | AC8: =(H9-H8)/H8 -> -0.14586684 | AD8: =(I9-I8)/I8 -> 0.091261413 | ... AN8: =(S9-S8)/S8 -> 0.17608542
A9: 36739 | B9: 10.155431 | C9: 14.096567 | D9: 26.94368 | E9: 306.83374 | F9: 6.795006 | G9: 7.219227 | H9: 10.101592 | I9: 15.7987 | J9: 13.900964 | K9: 15.839588 | L9: 36.565826 | M9: 28.610916 | N9: 10.770142 | O9: 5.288276 | P9: 0.91379 | Q9: 2.075 | R9: 21.362597 | S9: 65.488129 | V9: 36739 | W9: =(B10-B9)/B9 -> 0.087883419 | X9: =(C10-C9)/C9 -> -0.012753247 | Y9: =(D10-D9)/D9 -> -0.17337858 | Z9: =(E10-E9)/E9 -> -0.071691813 | AA9: =(F10-F9)/F9 -> 0.11013883 | AB9: =(G10-G9)/G9 -> -0.054833156 | AC9: =(H10-H9)/H9 -> 0.0094875144 | AD9: =(I10-I9)/I9 -> 0.083648338 | ... AN9: =(S10-S9)/S9 -> -0.14592622
A10: 36770 | B10: 11.047925 | C10: 13.91679 | D10: 22.272223 | E10: 284.83627 | F10: 7.5434 | G10: 6.823374 | H10: 10.197431 | I10: 17.120235 | J10: 12.081349 | K10: 16.529016 | L10: 37.640427 | M10: 28.774641 | N10: 11.513293 | O10: 5.461852 | P10: 0.386134 | Q10: 1.921875 | R10: 18.455601 | S10: 55.931694 | V10: 36770 | W10: =(B11-B10)/B10 -> 0.068400265 | X10: =(C11-C10)/C10 -> -0.0823386 | Y10: =(D11-D10)/D10 -> -0.014884774 | Z10: =(E11-E10)/E10 -> -0.026589447 | AA10: =(F11-F10)/F10 -> 0.026279264 | AB10: =(G11-G10)/G10 -> 0.24641094 | AC10: =(H11-H10)/H10 -> 0.11483735 | AD10: =(I11-I10)/I10 -> 0.066232444 | ... AN10: =(S11-S10)/S10 -> -0.12541673
A11: 36800 | B11: 11.803606 | C11: 12.770901 | D11: 21.940706 | E11: 277.26263 | F11: 7.741635 | G11: 8.504728 | H11: 11.368477 | I11: 18.25415 | J11: 13.947567 | K11: 15.890861 | L11: 37.17572 | M11: 26.899025 | N11: 11.607274 | O11: 5.147895 | P11: 0.29335 | Q11: 1.83125 | R11: 21.07572 | S11: 48.916924 | V11: 36800 | W11: =(B12-B11)/B11 -> -0.043386233 | X11: =(C12-C11)/C11 -> -0.16905064 | Y11: =(D12-D11)/D11 -> -0.18397489 | Z11: =(E12-E11)/E11 -> -0.053443887 | AA11: =(F12-F11)/F11 -> 0.0040437194 | AB11: =(G12-G11)/G11 -> -0.063339121 | AC11: =(H12-H11)/H11 -> 0.105263 | AD11: =(I12-I11)/I11 -> 0.053145997 | ... AN11: =(S12-S11)/S11 -> -0.050761368
A12: 36831 | B12: 11.291492 | C12: 10.611972 | D12: 17.904167 | E12: 262.44464 | F12: 7.77294 | G12: 7.966046 | H12: 12.565157 | I12: 19.224285 | J12: 14.11127 | K12: 16.3048 | L12: 34.083366 | M12: 25.846861 | N12: 11.889239 | O12: 4.844389 | P12: 0.247426 | Q12: 1.234375 | R12: 17.55673 | S12: 46.433834 | V12: 36831 | W12: =(B13-B12)/B12 -> 0.13938061 | X12: =(C13-C12)/C12 -> 0.16477512 | Y12: =(D13-D12)/D12 -> 0.23220371 | Z12: =(E13-E12)/E12 -> 0.027878485 | AA12: =(F13-F12)/F12 -> 0.14387593 | AB12: =(G13-G12)/G12 -> 0.14754057 | AC12: =(H13-H12)/H12 -> 0.12596015 | AD12: =(I13-I12)/I12 -> 0.047579715 | ... AN12: =(S13-S12)/S12 -> -0.089752248
A13: 36861 | B13: 12.865307 | C13: 12.360561 | D13: 22.061581 | E13: 269.7612 | F13: 8.891279 | G13: 9.141361 | H13: 14.147866 | I13: 20.138971 | J13: 16.491686 | K13: 16.961376 | L13: 34.083366 | M13: 29.421505 | N13: 14.02963 | O13: 5.416376 | P13: 0.223058 | Q13: 0.778125 | R13: 13.272737 | S13: 42.266293 | V13: 36861 | W13: =(B14-B13)/B13 -> 0.017475603 | X13: =(C14-C13)/C13 -> 0.17318826 | Y13: =(D14-D13)/D13 -> 0.2102338 | Z13: =(E14-E13)/E13 -> 0.096107205 | AA13: =(F14-F13)/F13 -> 0.036488789 | AB13: =(G14-G13)/G13 -> 0.27314324 | AC13: =(H14-H13)/H13 -> -0.058648138 | AD13: =(I14-I13)/I13 -> -0.084111894 | ... AN13: =(S14-S13)/S13 -> 0.31764702
... A298: 45536 | B298: 11.841108 | C298: 38.51656 | D298: 205.23119 | E298: 60.374752 | F298: 86.17878 | G298: 14.742605 | H298: 410.09845 | I298: 167.75551 | J298: 104.63736 | K298: 26.574545 | L298: 267.61038 | M298: 54.842106 | N298: 54.971821 | O298: 60.254768 | P298: 231.69604 | Q298: 186.33 | R298: 427.09357 | S298: 213.82654 | V298: 45536 | W298: =(B299-B298)/B298 -> 0.021399264 | X298: =(C299-C298)/C298 -> 0.060802496 | Y298: =(D299-D298)/D298 -> 0.052451848 | Z298: =(E299-E298)/E298 -> 0.025079871 | AA298: =(F299-F298)/F298 -> 0.010199611 | AB298: =(G299-G298)/G298 -> -0.010587681 | AC298: =(H299-H298)/H298 -> -0.026865469 | AD298: =(I299-I298)/I298 -> -0.046304787 | ... AN298: =(S299-S298)/S298 -> -0.064953911
A299: 45566 | B299: 12.094499 | C299: 40.858463 | D299: 215.99594 | E299: 61.888943 | F299: 87.05777 | G299: 14.586515 | H299: 399.08096 | I299: 159.98762 | J299: 89.017822 | K299: 25.986853 | L299: 266.50519 | M299: 55.009575 | N299: 63.175266 | O299: 52.644341 | P299: 224.64571 | Q299: 186.39999 | R299: 403.32208 | S299: 199.93767 | V299: 45566 | X299: =(C300-C299)/C299 -> -1 | Y299: =(D300-D299)/D299 -> -1 | Z299: =(E300-E299)/E299 -> -1 | AA299: =(F300-F299)/F299 -> -1 | AB299: =(G300-G299)/G299 -> -1 | AC299: =(H300-H299)/H299 -> -1 | AD299: =(I300-I299)/I299 -> -1 | AE299: =(J300-J299)/J299 -> -1 | ... AN299: =(S300-S299)/S299 -> -1

Sheet Q3
A1: date | B1: BCS | C1: BAC | D1: JPM | E1: C | F1: BMO | G1: M | H1: DE | I1: PG | J1: SWK | K1: PFE | L1: AXP | M1: NYT | N1: WFC | O1: TD | P1: AAPL | Q1: AMZN | R1: MSFT | S1: IBM | T1: SP500
A2: 36526 | B2: 9.444137 | C2: 12.490797 | D2: 25.48102 | E2: 223.44882 | F2: 5.332372 | G2: 10.871688 | H2: 13.243672 | I2: 25.479961 | J2: 12.81861 | K2: 13.227181 | L2: 33.865257 | M2: 33.154583 | N2: 9.864648 | O2: 4.590513 | P2: 0.777893 | Q2: 3.228125 | R2: 29.949718 | S2: 55.557552 | T2: 1394.46
A3: 36557 | B3: 9.49232 | C3: 11.862234 | D3: 25.28776 | E3: 202.86803 | F3: 4.881327 | G3: 9.582105 | H3: 10.837457 | I3: 22.215918 | J3: 11.734449 | K3: 11.74227 | L3: 27.62406 | M3: 30.660074 | N3: 8.153743 | O3: 4.613241 | P3: 0.859431 | Q3: 3.44375 | R3: 27.348722 | S3: 50.855602 | T3: 1366.42
A4: 36586 | B4: 10.845604 | C4: 13.5223 | D4: 27.689497 | E4: 235.37128 | F4: 5.716522 | G4: 11.034926 | H4: 11.519531 | I4: 14.347125 | J4: 13.456355 | K4: 13.398168 | L4: 30.660519 | M4: 31.24161 | N4: 10.10458 | O4: 4.851855 | P4: 1.01829 | Q4: 3.35 | R4: 32.512463 | S4: 58.650761 | T4: 1498.58
A5: 36617 | B5: 10.845604 | C5: 12.774712 | D5: 22.905861 | E5: 231.93176 | F5: 5.970817 | G5: 8.880181 | H5: 12.312965 | I5: 15.105558 | J5: 15.195655 | K5: 15.436522 | L5: 30.776304 | M5: 29.968321 | N5: 10.182076 | O5: 4.24007 | P5: 0.930191 | Q5: 2.759375 | R5: 21.343477 | S5: 55.24445 | T5: 1452.4301
A6: 36647 | B6: 10.549819 | C6: 14.453019 | D6: 23.843388 | E6: 245.08933 | F6: 6.621809 | G6: 10.055499 | H6: 12.675116 | I6: 16.890381 | J6: 13.843509 | K6: 16.306826 | L6: 33.407055 | M6: 28.058348 | N6: 11.220428 | O6: 4.503644 | P6: 0.629812 | Q6: 2.415625 | R6: 19.1441 | S6: 53.169697 | T6: 1420.6
A7: 36678 | B7: 9.859642 | C7: 11.313426 | D7: 22.057642 | E7: 237.45337 | F7: 7.042474 | G7: 8.814885 | H7: 11.283709 | I7: 14.413969 | J7: 12.233794 | K7: 17.623777 | L7: 32.247082 | M7: 28.827568 | N7: 9.660019 | O7: 4.457804 | P7: 0.785391 | Q7: 1.815625 | R7: 24.479969 | S7: 54.349976 | T7: 1454.6
A8: 36708 | B8: 8.959947 | C8: 12.464503 | D8: 23.853384 | E8: 277.85001 | F8: 7.094028 | G8: 6.284685 | H8: 11.826718 | I8: 14.477466 | J8: 13.600714 | K8: 15.92565 | L8: 35.069672 | M8: 30.059128 | N8: 10.345565 | O8: 4.420399 | P8: 0.76196 | Q8: 1.50625 | R8: 21.362597 | S8: 55.68314 | T8: 1430.83
A9: 36739 | B9: 10.155431 | C9: 14.096567 | D9: 26.94368 | E9: 306.83374 | F9: 6.795006 | G9: 7.219227 | H9: 10.101592 | I9: 15.7987 | J9: 13.900964 | K9: 15.839588 | L9: 36.565826 | M9: 28.610916 | N9: 10.770142 | O9: 5.288276 | P9: 0.91379 | Q9: 2.075 | R9: 21.362597 | S9: 65.488129 | T9: 1517.6801
A10: 36770 | B10: 11.047925 | C10: 13.91679 | D10: 22.272223 | E10: 284.83627 | F10: 7.5434 | G10: 6.823374 | H10: 10.197431 | I10: 17.120235 | J10: 12.081349 | K10: 16.529016 | L10: 37.640427 | M10: 28.774641 | N10: 11.513293 | O10: 5.461852 | P10: 0.386134 | Q10: 1.921875 | R10: 18.455601 | S10: 55.931694 | T10: 1436.51
A11: 36800 | B11: 11.803606 | C11: 12.770901 | D11: 21.940706 | E11: 277.26263 | F11: 7.741635 | G11: 8.504728 | H11: 11.368477 | I11: 18.25415 | J11: 13.947567 | K11: 15.890861 | L11: 37.17572 | M11: 26.899025 | N11: 11.607274 | O11: 5.147895 | P11: 0.29335 | Q11: 1.83125 | R11: 21.07572 | S11: 48.916924 | T11: 1429.4
A12: 36831 | B12: 11.291492 | C12: 10.611972 | D12: 17.904167 | E12: 262.44464 | F12: 7.77294 | G12: 7.966046 | H12: 12.565157 | I12: 19.224285 | J12: 14.11127 | K12: 16.3048 | L12: 34.083366 | M12: 25.846861 | N12: 11.889239 | O12: 4.844389 | P12: 0.247426 | Q12: 1.234375 | R12: 17.55673 | S12: 46.433834 | T12: 1314.95
A13: 36861 | B13: 12.865307 | C13: 12.360561 | D13: 22.061581 | E13: 269.7612 | F13: 8.891279 | G13: 9.141361 | H13: 14.147866 | I13: 20.138971 | J13: 16.491686 | K13: 16.961376 | L13: 34.083366 | M13: 29.421505 | N13: 14.02963 | O13: 5.416376 | P13: 0.223058 | Q13: 0.778125 | R13: 13.272737 | S13: 42.266293 | T13: 1320.28
... A299: 45566 | B299: 12.094499 | C299: 40.858463 | D299: 215.99594 | E299: 61.888943 | F299: 87.05777 | G299: 14.586515 | H299: 399.08096 | I299: 159.98762 | J299: 89.017822 | K299: 25.986853 | L299: 266.50519 | M299: 55.009575 | N299: 63.175266 | O299: 52.644341 | P299: 224.64571 | Q299: 186.39999 | R299: 403.32208 | S299: 199.93767 | T299: 5705.4502

Sheet Q1.
